Workbook

Sheet Avance
C2: Junta Local Ejecutiva en el Estado de México
C3: Vocalía de Capacitación Electoral y Educación Cívica
C5: Proceso Electoral Concurrente 2026-2027
C6: Reporte sobre el avance del proceso de recontratación
B8: Fecha de corte: | D8: 46316
B9: Nota: en los casos de las personas que hayan participado en más de un proceso electoral, únicamente se deberá registrar su participación en el más reciente, con el fin de evitar duplicidades.
B10: Entidad | C10: Distrito | D10: Cabecera | E10: Proceso Electoral Concurrente 2023-2024 | J10: Proceso Electoral Extraordinario para la elección de diversos cargos del Poder Judicial de la Federación 2024-2025 | O10: Proceso Electoral Local 2024-2025 Durango y Veracruz Proceso Electoral Local 2025-2026 Coahuila | T10: Total de personas contactadas | U10: Observaciones (en su caso)
E11: Número de personas contactadas | F11: Número de personas interesadas | G11: Número de personas no interesadas | H11: Número de personas sin respuesta | I11: Número de personas entrevistadas | J11: Número de personas contactadas | K11: Número de personas interesadas | L11: Número de personas no interesadas | M11: Número de personas sin respuesta | N11: Número de personas entrevistadas | O11: Número de personas contactadas | P11: Número de personas interesadas | Q11: Número de personas no interesadas | R11: Número de personas sin respuesta | S11: Número de personas entrevistadas
B12: A dos digitos | C12: A dos digitos
B13: 15 | C13: 01 | D13: Jilotepec de Andrés Molina Enriquez | E13: 129 | F13: 93 | G13: 16 | H13: 20 | I13: 0 | J13: 56 | K13: 49 | L13: 3 | M13: 4 | N13: 0 | O13: No aplica | P13: No aplica | Q13: No aplica | R13: No aplica | S13: No aplica | T13: =SUM(E13,J13,O13) -> 185
B14: 15 | C14: 02 | D14: Santa María Tultepec | E14: 5 | F14: 2 | G14: 3 | H14: 0 | I14: 0 | J14: 135 | K14: 87 | L14: 28 | M14: 20 | N14: 0 | O14: No aplica | P14: No aplica | Q14: No aplica | R14: No aplica | S14: No aplica | T14: =SUM(E14,J14,O14) -> 140
B15: 15 | C15: 03 | D15: Atlacomulco de Fabela | E15: 86 | F15: 46 | G15: 5 | H15: 35 | J15: 63 | K15: 58 | L15: 0 | M15: 5 | O15: No aplica | P15: No aplica | Q15: No aplica | R15: No aplica | S15: No aplica | T15: =SUM(E15,J15,O15) -> 149
B16: 15 | C16: 04 | D16: Ciudad Nicolas Romero y/o Centro Histórico San Pedro Azcapotzaltongo | E16: 138 | F16: 60 | G16: 9 | H16: 69 | I16: 0 | J16: 52 | K16: 34 | L16: 7 | M16: 11 | N16: 0 | O16: No aplica | P16: No aplica | Q16: No aplica | R16: No aplica | S16: No aplica | T16: =SUM(E16,J16,O16) -> 190 | U16: 34 personas personas pertenecen a PEC 23-24 y PEE PJF
B17: 15 | C17: 05 | D17: Teotihuacan de Arista | E17: 78 | F17: 43 | G17: 13 | H17: 22 | I17: 0 | J17: 53 | K17: 48 | L17: 2 | M17: 3 | N17: 0 | O17: No aplica | P17: No aplica | Q17: No aplica | R17: No aplica | S17: No aplica | T17: =SUM(E17,J17,O17) -> 131
B18: 15 | C18: 06 | D18: Coacalco de Berriozabal | E18: 91 | F18: 37 | G18: 11 | H18: 43 | I18: 0 | J18: 71 | K18: 64 | L18: 4 | M18: 3 | N18: 0 | O18: No aplica | P18: No aplica | Q18: No aplica | R18: No aplica | S18: No aplica | T18: =SUM(E18,J18,O18) -> 162
B19: 15 | C19: 07 | D19: Cuautitlán Izcalli | E19: 87 | F19: 60 | G19: 8 | H19: 19 | I19: 0 | J19: 44 | K19: 39 | L19: 1 | M19: 4 | N19: 0 | O19: No aplica | P19: No aplica | Q19: No aplica | R19: No aplica | S19: No aplica | T19: =SUM(E19,J19,O19) -> 131
B20: 15 | C20: 08 | D20: Tultitlan de Mariano Escobedo | E20: 78 | F20: 42 | G20: 14 | H20: 22 | I20: 0 | J20: 89 | K20: 74 | L20: 6 | M20: 9 | N20: 0 | O20: No aplica | P20: No aplica | Q20: No aplica | R20: No aplica | S20: No aplica | T20: =SUM(E20,J20,O20) -> 167
B21: 15 | C21: 09 | D21: San Felipe del Progreso | E21: 73 | F21: 29 | G21: 12 | H21: 32 | I21: 0 | J21: 42 | K21: 35 | L21: 0 | M21: 7 | N21: 0 | O21: No aplica | P21: No aplica | Q21: No aplica | R21: No aplica | S21: No aplica | T21: =SUM(E21,J21,O21) -> 115
B22: 15 | C22: 10 | D22: Ecatepec de Morelos | E22: 81 | F22: 51 | G22: 17 | H22: 13 | I22: 0 | J22: 61 | K22: 56 | L22: 5 | M22: 0 | N22: 0 | O22: No aplica | P22: No aplica | Q22: No aplica | R22: No aplica | S22: No aplica | T22: =SUM(E22,J22,O22) -> 142
B23: 15 | C23: 11 | D23: Ecatepec de Morelos | E23: 80 | F23: 12 | G23: 30 | H23: 38 | I23: 0 | J23: 68 | K23: 62 | L23: 4 | M23: 2 | N23: 0 | O23: No aplica | P23: No aplica | Q23: No aplica | R23: No aplica | S23: No aplica | T23: =SUM(E23,J23,O23) -> 148
B24: 15 | C24: 12 | D24: Ixtapaluca | E24: 65 | F24: 28 | G24: 15 | H24: 22 | I24: 0 | J24: 63 | K24: 52 | L24: 10 | M24: 1 | N24: 0 | O24: No aplica | P24: No aplica | Q24: No aplica | R24: No aplica | S24: No aplica | T24: =SUM(E24,J24,O24) -> 128
B25: 15 | C25: 13 | D25: Ecatepec de Morelos | E25: 121 | F25: 55 | G25: 20 | H25: 46 | I25: 0 | J25: 80 | K25: 72 | L25: 3 | M25: 5 | N25: 0 | O25: No aplica | P25: No aplica | Q25: No aplica | R25: No aplica | S25: No aplica | T25: =SUM(E25,J25,O25) -> 201
B26: 15 | C26: 14 | D26: Tepexpan | E26: 122 | F26: 64 | G26: 26 | H26: 32 | I26: 0 | J26: 7 | K26: 4 | L26: 2 | M26: 1 | N26: 0 | O26: No aplica | P26: No aplica | Q26: No aplica | R26: No aplica | S26: No aplica | T26: =SUM(E26,J26,O26) -> 129
B27: 15 | C27: 15 | D27: Ciudad Adolfo López Mateos | E27: 70 | F27: 29 | G27: 10 | H27: 31 | I27: 0 | J27: 66 | K27: 50 | L27: 7 | M27: 9 | N27: 0 | O27: No aplica | P27: No aplica | Q27: No aplica | R27: No aplica | S27: No aplica | T27: =SUM(E27,J27,O27) -> 136
B28: 15 | C28: 16 | D28: Ecatepec de Morelos | E28: 86 | F28: 53 | G28: 11 | H28: 22 | I28: 0 | J28: 63 | K28: 61 | L28: 2 | M28: 0 | N28: 0 | O28: No aplica | P28: No aplica | Q28: No aplica | R28: No aplica | S28: No aplica | T28: =SUM(E28,J28,O28) -> 149 | U28: El total de personas que concluyeron en el PEC 2023-2024 fueron 151. Se contactaron 149, porque dos personas fallecieron en 2025.
B29: 15 | C29: 17 | D29: Ecatepec de Morelos | E29: 127 | F29: 89 | G29: 22 | H29: 16 | I29: 0 | J29: 57 | K29: 51 | L29: 6 | M29: 0 | N29: 0 | O29: No aplica | P29: No aplica | Q29: No aplica | R29: No aplica | S29: No aplica | T29: =SUM(E29,J29,O29) -> 184
B30: 15 | C30: 18 | D30: Huixquilucan de Degollado | E30: 95 | F30: 31 | G30: 17 | H30: 47 | I30: 0 | J30: 71 | K30: 62 | L30: 3 | M30: 6 | N30: 0 | O30: No aplica | P30: No aplica | Q30: No aplica | R30: No aplica | S30: No aplica | T30: =SUM(E30,J30,O30) -> 166
B31: 15 | C31: 19 | D31: Tlalnepantla de Baz | E31: 99 | F31: 23 | G31: 11 | H31: 65 | I31: 0 | J31: 94 | K31: 73 | L31: 2 | M31: 19 | N31: 0 | O31: No aplica | P31: No aplica | Q31: No aplica | R31: No aplica | S31: No aplica | T31: =SUM(E31,J31,O31) -> 193
B32: 15 | C32: 20 | D32: Ojo de Agua | E32: 56 | F32: 34 | G32: 9 | H32: 13 | I32: 0 | J32: 60 | K32: 53 | L32: 7 | M32: 0 | N32: 0 | O32: No aplica | P32: No aplica | Q32: No aplica | R32: No aplica | S32: No aplica | T32: =SUM(E32,J32,O32) -> 116 | U32: El total de personas que concluyeron el PEC 2023-2024 fueron 116. Se contactaron
B33: 15 | C33: 21 | D33: Amecameca de Juárez | E33: 67 | F33: 50 | G33: 17 | H33: 0 | I33: 0 | J33: 64 | K33: 54 | L33: 10 | M33: 0 | N33: 0 | O33: No aplica | P33: No aplica | Q33: No aplica | R33: No aplica | S33: No aplica | T33: =SUM(E33,J33,O33) -> 131 | U33: Adicionalmente, 15 del PEC 2023-2024 y 5 del PEEPJF 2024-2025, no se pudieron contactar.
B34: 15 | C34: 22 | D34: Naucalpan de Juárez | E34: 90 | F34: 40 | G34: 19 | H34: 31 | I34: 0 | J34: 82 | K34: 72 | L34: 7 | M34: 3 | N34: 0 | O34: No aplica | P34: No aplica | Q34: No aplica | R34: No aplica | S34: No aplica | T34: =SUM(E34,J34,O34) -> 172
B35: 15 | C35: 23 | D35: Lerma de Villada | E35: 57 | F35: 29 | G35: 18 | H35: 10 | I35: 0 | J35: 44 | K35: 39 | L35: 4 | M35: 1 | N35: 0 | O35: No aplica | P35: No aplica | Q35: No aplica | R35: No aplica | S35: No aplica | T35: =SUM(E35,J35,O35) -> 101
B36: 15 | C36: 24 | D36: Naucalpan de Juárez | E36: 69 | F36: 44 | G36: 16 | H36: 9 | I36: 0 | J36: 85 | K36: 70 | L36: 15 | M36: 0 | N36: 0 | O36: No aplica | P36: No aplica | Q36: No aplica | R36: No aplica | S36: No aplica | T36: =SUM(E36,J36,O36) -> 154
B37: 15 | C37: 25 | D37: Chimalhuacán | E37: 74 | F37: 41 | G37: 12 | H37: 21 | I37: 0 | J37: 55 | K37: 48 | L37: 7 | M37: 0 | N37: 0 | O37: No aplica | P37: No aplica | Q37: No aplica | R37: No aplica | S37: No aplica | T37: =SUM(E37,J37,O37) -> 129 | U37: 89 interesadas programadas para entrevista
B38: 15 | C38: 26 | D38: Toluca de Lerdo | E38: 92 | F38: 42 | G38: 16 | H38: 34 | I38: 0 | J38: 68 | K38: 50 | L38: 4 | M38: 14 | O38: No aplica | P38: No aplica | Q38: No aplica | R38: No aplica | S38: No aplica | T38: =SUM(E38,J38,O38) -> 160 | U38: 38 Figuras participarón en ambos PE
B39: 15 | C39: 27 | D39: Metepec | E39: 94 | F39: 50 | G39: 25 | H39: 19 | I39: 0 | J39: 54 | K39: 47 | L39: 6 | M39: 1 | N39: 0 | O39: No aplica | P39: No aplica | Q39: No aplica | R39: No aplica | S39: No aplica | T39: =SUM(E39,J39,O39) -> 148
B40: 15 | C40: 28 | D40: Zumpango de Ocampo | E40: 60 | F40: 26 | G40: 18 | H40: 16 | I40: 0 | J40: 55 | K40: 45 | L40: 8 | M40: 2 | N40: 0 | O40: No aplica | P40: No aplica | Q40: No aplica | R40: No aplica | S40: No aplica | T40: =SUM(E40,J40,O40) -> 115
B41: 15 | C41: 29 | D41: Cd. Nezahualcóyotl | E41: 105 | F41: 28 | G41: 0 | H41: 77 | I41: 0 | J41: 67 | K41: 67 | L41: 0 | M41: 0 | N41: 0 | O41: No aplica | P41: No aplica | Q41: No aplica | R41: No aplica | S41: No aplica | T41: =SUM(E41,J41,O41) -> 172
B42: 15 | C42: 30 | D42: Chimalhuacán | E42: 72 | F42: 49 | G42: 13 | H42: 10 | I42: 0 | J42: 55 | K42: 45 | L42: 10 | M42: 0 | N42: 0 | O42: No aplica | P42: No aplica | Q42: No aplica | R42: No aplica | S42: No aplica | T42: =SUM(E42,J42,O42) -> 127
B43: 15 | C43: 31 | D43: Cd. Nezahualcóyotl | E43: 105 | F43: 59 | G43: 22 | H43: 24 | I43: 0 | J43: 82 | K43: 62 | L43: 4 | M43: 16 | N43: 0 | O43: No aplica | P43: No aplica | Q43: No aplica | R43: No aplica | S43: No aplica | T43: =SUM(E43,J43,O43) -> 187
...

Sheet Hoja1
A1: Proceso Electoral Concurrente 2023-2024 | F1: Proceso Electoral Extraordinario para la elección de diversos cargos del Poder Judicial de la Federación 2024-2025 | M1: Total de Personas Contactadas
B2: Diferencia | C2: Sumatoria | G2: Diferencia | H2: Sumatoria | M2: Diferencia | N2: Sumatoria
A3: 1 | B3: =C3-Avance!E13 -> 0 | C3: =Avance!F13+Avance!G13+Avance!H13 -> 129 | G3: =H3-Avance!J13 -> 0 | H3: =Avance!K13+Avance!L13+Avance!M13 -> 56 | M3: =N3-Avance!T13 -> 0 | N3: =Avance!E13+Avance!J13 -> 185
A4: 2 | B4: =C4-Avance!E14 -> 0 | C4: =Avance!F14+Avance!G14+Avance!H14 -> 5 | G4: =H4-Avance!J14 -> 0 | H4: =Avance!K14+Avance!L14+Avance!M14 -> 135 | M4: =N4-Avance!T14 -> 0 | N4: =Avance!E14+Avance!J14 -> 140
A5: 3 | B5: =C5-Avance!E15 -> 0 | C5: =Avance!F15+Avance!G15+Avance!H15 -> 86 | G5: =H5-Avance!J15 -> 0 | H5: =Avance!K15+Avance!L15+Avance!M15 -> 63 | M5: =N5-Avance!T15 -> 0 | N5: =Avance!E15+Avance!J15 -> 149
A6: 4 | B6: =C6-Avance!E16 -> 0 | C6: =Avance!F16+Avance!G16+Avance!H16 -> 138 | G6: =H6-Avance!J16 -> 0 | H6: =Avance!K16+Avance!L16+Avance!M16 -> 52 | M6: =N6-Avance!T16 -> 0 | N6: =Avance!E16+Avance!J16 -> 190
A7: 5 | B7: =C7-Avance!E17 -> 0 | C7: =Avance!F17+Avance!G17+Avance!H17 -> 78 | G7: =H7-Avance!J17 -> 0 | H7: =Avance!K17+Avance!L17+Avance!M17 -> 53 | M7: =N7-Avance!T17 -> 0 | N7: =Avance!E17+Avance!J17 -> 131
A8: 6 | B8: =C8-Avance!E18 -> 0 | C8: =Avance!F18+Avance!G18+Avance!H18 -> 91 | G8: =H8-Avance!J18 -> 0 | H8: =Avance!K18+Avance!L18+Avance!M18 -> 71 | M8: =N8-Avance!T18 -> 0 | N8: =Avance!E18+Avance!J18 -> 162
A9: 7 | B9: =C9-Avance!E19 -> 0 | C9: =Avance!F19+Avance!G19+Avance!H19 -> 87 | G9: =H9-Avance!J19 -> 0 | H9: =Avance!K19+Avance!L19+Avance!M19 -> 44 | M9: =N9-Avance!T19 -> 0 | N9: =Avance!E19+Avance!J19 -> 131
A10: 8 | B10: =C10-Avance!E20 -> 0 | C10: =Avance!F20+Avance!G20+Avance!H20 -> 78 | G10: =H10-Avance!J20 -> 0 | H10: =Avance!K20+Avance!L20+Avance!M20 -> 89 | M10: =N10-Avance!T20 -> 0 | N10: =Avance!E20+Avance!J20 -> 167
A11: 9 | B11: =C11-Avance!E21 -> 0 | C11: =Avance!F21+Avance!G21+Avance!H21 -> 73 | G11: =H11-Avance!J21 -> 0 | H11: =Avance!K21+Avance!L21+Avance!M21 -> 42 | M11: =N11-Avance!T21 -> 0 | N11: =Avance!E21+Avance!J21 -> 115
A12: 10 | B12: =C12-Avance!E22 -> 0 | C12: =Avance!F22+Avance!G22+Avance!H22 -> 81 | G12: =H12-Avance!J22 -> 0 | H12: =Avance!K22+Avance!L22+Avance!M22 -> 61 | M12: =N12-Avance!T22 -> 0 | N12: =Avance!E22+Avance!J22 -> 142
A13: 11 | B13: =C13-Avance!E23 -> 0 | C13: =Avance!F23+Avance!G23+Avance!H23 -> 80 | G13: =H13-Avance!J23 -> 0 | H13: =Avance!K23+Avance!L23+Avance!M23 -> 68 | M13: =N13-Avance!T23 -> 0 | N13: =Avance!E23+Avance!J23 -> 148
A14: 12 | B14: =C14-Avance!E24 -> 0 | C14: =Avance!F24+Avance!G24+Avance!H24 -> 65 | G14: =H14-Avance!J24 -> 0 | H14: =Avance!K24+Avance!L24+Avance!M24 -> 63 | M14: =N14-Avance!T24 -> 0 | N14: =Avance!E24+Avance!J24 -> 128
... A42: 40 | B42: =C42-Avance!E52 -> 0 | C42: =Avance!F52+Avance!G52+Avance!H52 -> 93 | G42: =H42-Avance!J52 -> 0 | H42: =Avance!K52+Avance!L52+Avance!M52 -> 69 | M42: =N42-Avance!T52 -> 0 | N42: =Avance!E52+Avance!J52 -> 162
